Workbook

Sheet Balances
A1: wallet | B1: address | C1: total_usd | D1: wallet_tokens_usd | E1: defi_usd | F1: inbound_count | G1: inbound_total_usd | H1: external_receive_usd | I1: chain_count | J1: chain_breakdown | K1: top_holdings | L1: top_defi | M1: history_truncated
A2: Adamo OTC | B2: 0x2f58b30bd40fcb1806c2fb0b81e381a9881530bc | C2: 11246.92 | D2: 11246.92 | E2: 0 | F2: =COUNTIFS(Inbounds!$A$2:$A$375,$A2) | G2: =SUMIFS(Inbounds!$M$2:$M$375,Inbounds!$A$2:$A$375,$A2) | H2: =SUMIFS(Inbounds!$M$2:$M$375,Inbounds!$A$2:$A$375,$A2,Inbounds!$F$2:$F$375,"TRUE") | I2: 3 | J2: ethereum:11,246.57 | arbitrum:0.33 | monad:0.02 | K2: ETH 3.9041 ($7,654.49) [ethereum]; USDT 3,505.4212 ($3,514.49) [ethereum]; USDC 77.5758 ($77.59) [ethereum]; USDC 0.1920 ($0.19) [arbitrum]; USDT0 0.1333 ($0.13) [arbitrum]; MON 1.0000 ($0.02) [monad]; HEX 1.0000 ($0.00) [ethereum]; USDC 0.0009 ($0.00) [base]; ETH 0.0000 ($0.00) [arbitrum]; mUSD 0.0001 ($0.00) [ethereum] | M2: FALSE
A3: Brute OTC | B3: 0x9244a6962d8f2eefdcfec223f68d83df293d9797 | C3: 3783.6 | D3: 3783.6 | E3: 0 | F3: =COUNTIFS(Inbounds!$A$2:$A$375,$A3) | G3: =SUMIFS(Inbounds!$M$2:$M$375,Inbounds!$A$2:$A$375,$A3) | H3: =SUMIFS(Inbounds!$M$2:$M$375,Inbounds!$A$2:$A$375,$A3,Inbounds!$F$2:$F$375,"TRUE") | I3: 2 | J3: ethereum:3,783.51 | arbitrum:0.08 | K3: USDT 2,445.1122 ($2,451.44) [ethereum]; ETH 0.3692 ($725.12) [ethereum]; USDC 561.9007 ($564.58) [ethereum]; PYUSD 42.1575 ($42.36) [ethereum]; USDT0 0.0826 ($0.08) [arbitrum]; USDT 0.0018 ($0.00) [base]; HEX 1.0000 ($0.00) [ethereum]; AVAX 0.0000 ($0.00) [avalanche]; SHIB 4.1175 ($0.00) [ethereum]; PEPE 5.2000 ($0.00) [ethereum] | M3: FALSE
A4: SP4-1 | B4: 0x13c5738200a7ca56c29e5744a3e93f52abd77d7b | C4: 74085.68 | D4: 74085.68 | E4: 0 | F4: =COUNTIFS(Inbounds!$A$2:$A$375,$A4) | G4: =SUMIFS(Inbounds!$M$2:$M$375,Inbounds!$A$2:$A$375,$A4) | H4: =SUMIFS(Inbounds!$M$2:$M$375,Inbounds!$A$2:$A$375,$A4,Inbounds!$F$2:$F$375,"TRUE") | I4: 1 | J4: ethereum:74,085.68 | K4: USDT 72,937.5000 ($72,892.39) [ethereum]; USDC 1,180.0000 ($1,183.47) [ethereum]; ETH 0.0050 ($9.82) [ethereum] | M4: FALSE
A5: SP4-2 | B5: 0x31a5817bab67bfeeb0038df2c2e1ede79a00930a | C5: 19878.64 | D5: 19878.64 | E5: 0 | F5: =COUNTIFS(Inbounds!$A$2:$A$375,$A5) | G5: =SUMIFS(Inbounds!$M$2:$M$375,Inbounds!$A$2:$A$375,$A5) | H5: =SUMIFS(Inbounds!$M$2:$M$375,Inbounds!$A$2:$A$375,$A5,Inbounds!$F$2:$F$375,"TRUE") | I5: 2 | J5: ethereum:19,868.87 | binance-smart-chain:9.76 | K5: USDT 19,774.0600 ($19,760.93) [ethereum]; PYUSD 95.0927 ($95.56) [ethereum]; ETH 0.0063 ($12.38) [ethereum]; WETH 0.0050 ($9.76) [binance-smart-chain] | M5: FALSE
A6: SP4-3 | B6: 0x691bdfb0c5a8dee9f75de8bc983bde51316eb489 | C6: 1421.71 | D6: 1421.71 | E6: 0 | F6: =COUNTIFS(Inbounds!$A$2:$A$375,$A6) | G6: =SUMIFS(Inbounds!$M$2:$M$375,Inbounds!$A$2:$A$375,$A6) | H6: =SUMIFS(Inbounds!$M$2:$M$375,Inbounds!$A$2:$A$375,$A6,Inbounds!$F$2:$F$375,"TRUE") | I6: 1 | J6: ethereum:1,421.71 | K6: USDC 1,380.0001 ($1,386.59) [ethereum]; ETH 0.0179 ($35.11) [ethereum] | M6: FALSE
A7: SP4-4 | B7: 0x0828c3d976b837e790715913cc85dbd6237398fb | C7: 3997.34 | D7: 3997.34 | E7: 0 | F7: =COUNTIFS(Inbounds!$A$2:$A$375,$A7) | G7: =SUMIFS(Inbounds!$M$2:$M$375,Inbounds!$A$2:$A$375,$A7) | H7: =SUMIFS(Inbounds!$M$2:$M$375,Inbounds!$A$2:$A$375,$A7,Inbounds!$F$2:$F$375,"TRUE") | I7: 1 | J7: ethereum:3,997.34 | K7: USDT 4,000.0000 ($3,997.34) [ethereum]; ETH 0.0000 ($0.00) [ethereum] | M7: FALSE
A8: SP4-5 | B8: 0x79b65b17af2ec4087d0957bcfae172c3c6210312 | C8: 51606.87 | D8: 51606.87 | E8: 0 | F8: =COUNTIFS(Inbounds!$A$2:$A$375,$A8) | G8: =SUMIFS(Inbounds!$M$2:$M$375,Inbounds!$A$2:$A$375,$A8) | H8: =SUMIFS(Inbounds!$M$2:$M$375,Inbounds!$A$2:$A$375,$A8,Inbounds!$F$2:$F$375,"TRUE") | I8: 1 | J8: ethereum:51,606.87 | K8: USDC 51,450.4738 ($51,601.77) [ethereum]; ETH 0.0026 ($5.10) [ethereum] | M8: FALSE
A9: SP4-6 | B9: 0x82012f9fdddaaf6a8af4ef2b83b1c6ce65debcf1 | C9: 43494.75 | D9: 43494.75 | E9: 0 | F9: =COUNTIFS(Inbounds!$A$2:$A$375,$A9) | G9: =SUMIFS(Inbounds!$M$2:$M$375,Inbounds!$A$2:$A$375,$A9) | H9: =SUMIFS(Inbounds!$M$2:$M$375,Inbounds!$A$2:$A$375,$A9,Inbounds!$F$2:$F$375,"TRUE") | I9: 1 | J9: ethereum:43,494.75 | K9: USDT 28,859.9587 ($28,987.62) [ethereum]; USDC 14,511.0000 ($14,506.21) [ethereum]; ETH 0.0005 ($0.92) [ethereum] | M9: FALSE
A10: SP4-7 | B10: 0xc4a749d6983bfc2bb958cb32ef9ff9dc18ba81cf | C10: 11636.16 | D10: 11636.16 | E10: 0 | F10: =COUNTIFS(Inbounds!$A$2:$A$375,$A10) | G10: =SUMIFS(Inbounds!$M$2:$M$375,Inbounds!$A$2:$A$375,$A10) | H10: =SUMIFS(Inbounds!$M$2:$M$375,Inbounds!$A$2:$A$375,$A10,Inbounds!$F$2:$F$375,"TRUE") | I10: 1 | J10: ethereum:11,636.16 | K10: USDC 11,640.0000 ($11,636.16) [ethereum] | M10: FALSE
A11: SP4-8 | B11: 0xc09da08738b3b0918089163e488b02a61f382404 | C11: 81486.45 | D11: 81486.45 | E11: 0 | F11: =COUNTIFS(Inbounds!$A$2:$A$375,$A11) | G11: =SUMIFS(Inbounds!$M$2:$M$375,Inbounds!$A$2:$A$375,$A11) | H11: =SUMIFS(Inbounds!$M$2:$M$375,Inbounds!$A$2:$A$375,$A11,Inbounds!$F$2:$F$375,"TRUE") | I11: 1 | J11: ethereum:81,486.45 | K11: USDT 81,308.5207 ($81,476.69) [ethereum]; ETH 0.0050 ($9.76) [ethereum] | M11: FALSE
A12: SP4-9 | B12: 0x28aa29d3cb526d4d8e9492bf42ed04aff45388f5 | C12: 0 | D12: 0 | E12: 0 | F12: =COUNTIFS(Inbounds!$A$2:$A$375,$A12) | G12: =SUMIFS(Inbounds!$M$2:$M$375,Inbounds!$A$2:$A$375,$A12) | H12: =SUMIFS(Inbounds!$M$2:$M$375,Inbounds!$A$2:$A$375,$A12,Inbounds!$F$2:$F$375,"TRUE") | I12: 0 | M12: FALSE
A13: SP4-10 | B13: 0x2acfb4445a3936e3951802245d8820d35e51d597 | C13: 0 | D13: 0 | E13: 0 | F13: =COUNTIFS(Inbounds!$A$2:$A$375,$A13) | G13: =SUMIFS(Inbounds!$M$2:$M$375,Inbounds!$A$2:$A$375,$A13) | H13: =SUMIFS(Inbounds!$M$2:$M$375,Inbounds!$A$2:$A$375,$A13,Inbounds!$F$2:$F$375,"TRUE") | I13: 0 | M13: FALSE
A14: TOTAL | C14: =SUM(C2:C13) | D14: =SUM(D2:D13) | E14: =SUM(E2:E13) | F14: =SUM(F2:F13) | G14: =SUM(G2:G13) | H14: =SUM(H2:H13)

Sheet Inbounds
A1: wallet | B1: address | C1: datetime_utc | D1: date_utc | E1: operation_type | F1: external_receive | G1: internal_transfer | H1: chain | I1: token | J1: token_name | K1: amount | L1: price_usd | M1: usd_value | N1: sender | O1: sender_label | P1: tx_hash
A2: Adamo OTC | B2: 0x2f58b30bd40fcb1806c2fb0b81e381a9881530bc | C2: 2026-06-11 03:07:59 | D2: 2026-06-11 | E2: receive | F2: TRUE | G2: FALSE | H2: ethereum | I2: USDT | J2: Tether USD | K2: 3257.18 | L2: 0.998365 | M2: 3251.85 | N2: 0xba1e36ab637a9a2e3929222a5b7f081a6960e9e8 | P2: 0x9d019d36a2dce3b8881c9631ef18695eedbe1bd6825c6b9c0a46618596fbba58
A3: Adamo OTC | B3: 0x2f58b30bd40fcb1806c2fb0b81e381a9881530bc | C3: 2026-06-01 16:07:47 | D3: 2026-06-01 | E3: receive | F3: TRUE | G3: FALSE | H3: ethereum | I3: USDT | J3: Tether USD | K3: 32760.189 | L3: 0.998682 | M3: 32717.01 | N3: 0x399740157391a9f1bf4e9921a8834f9bc8f2678e | P3: 0x9282c63d1ac0bca84bf47f0089ba5a9a09ae2386f7ac8551e18980c33dac5628
A4: Adamo OTC | B4: 0x2f58b30bd40fcb1806c2fb0b81e381a9881530bc | C4: 2026-06-01 16:07:23 | D4: 2026-06-01 | E4: receive | F4: TRUE | G4: TRUE | H4: ethereum | I4: USDT | J4: Tether USD | K4: 31187.429 | L4: 0.9982 | M4: 31131.29 | N4: 0x9244a6962d8f2eefdcfec223f68d83df293d9797 | O4: Brute OTC | P4: 0x3ba7f8fea5f144b7316423c291d5acdcea39430ccad92226fd4570265d0e3fa4
A5: Adamo OTC | B5: 0x2f58b30bd40fcb1806c2fb0b81e381a9881530bc | C5: 2026-05-21 19:53:35 | D5: 2026-05-21 | E5: receive | F5: TRUE | G5: FALSE | H5: ethereum | I5: USDC | J5: USDC | K5: 428.02821 | L5: 1.000152 | M5: 428.09 | N5: 0x1fdd2c6600312df1e1ce1f1ff4cabe504a09c352 | P5: 0xc97331eae0b6de4aa888ac456c2e2653e575fd2aec729919b89885d511486089
A6: Adamo OTC | B6: 0x2f58b30bd40fcb1806c2fb0b81e381a9881530bc | C6: 2026-05-04 21:17:47 | D6: 2026-05-04 | E6: receive | F6: TRUE | G6: FALSE | H6: ethereum | I6: USDT | J6: Tether USD | K6: 780 | L6: 0.999797 | M6: 779.84 | N6: 0xaa8ba7d4611437141192e7ceced531bc0a133efb | P6: 0x07e11e92be8cfb6640dfd5366f6d85b465dc916f93bfe931b9900c74ee55bfc4
A7: Adamo OTC | B7: 0x2f58b30bd40fcb1806c2fb0b81e381a9881530bc | C7: 2026-05-04 21:12:11 | D7: 2026-05-04 | E7: receive | F7: TRUE | G7: FALSE | H7: ethereum | I7: USDT | J7: Tether USD | K7: 22425 | L7: 0.999512 | M7: 22414.05 | N7: 0xaa8ba7d4611437141192e7ceced531bc0a133efb | P7: 0xe9fbe48e9091af571c0e0d567aea1e598ed9e883c2644f595ab5e3d95ba1288b
A8: Adamo OTC | B8: 0x2f58b30bd40fcb1806c2fb0b81e381a9881530bc | C8: 2026-05-01 18:55:11 | D8: 2026-05-01 | E8: receive | F8: TRUE | G8: FALSE | H8: ethereum | I8: ETH | J8: Ethereum | K8: 12.6249 | L8: 2306.42 | M8: 29118.32 | N8: 0x6116f484534d113d423c6b5b302d69c665a2d37b | P8: 0x169c0ee1ea6e7f77ff6219a8a25e3d822cbef76d8095355ca7645072994e305c
A9: Adamo OTC | B9: 0x2f58b30bd40fcb1806c2fb0b81e381a9881530bc | C9: 2026-05-01 18:24:35 | D9: 2026-05-01 | E9: receive | F9: TRUE | G9: FALSE | H9: ethereum | I9: USDC | J9: USDC | K9: 24390.25 | L9: 1.000507 | M9: 24402.62 | N9: 0x003596b3ed9f0508a15926288306a23667aa99c6 | P9: 0x8e2a9a13ac46b671be89d15ffe63f8f61cd32166e065f6ad2cc15a5dd78a0eb8
A10: Adamo OTC | B10: 0x2f58b30bd40fcb1806c2fb0b81e381a9881530bc | C10: 2026-04-30 02:01:59 | D10: 2026-04-30 | E10: receive | F10: TRUE | G10: FALSE | H10: ethereum | I10: USDT | J10: Tether USD | K10: 86410 | L10: 0.999518 | M10: 86368.32 | N10: 0x680a9c6e781f0ca940e4632ae9bbac3d0ee3b0de | P10: 0xbf2baaf6abda78fbf71e19152b09e7ad74d7af4678e044541d95d277c65ebf91
A11: Adamo OTC | B11: 0x2f58b30bd40fcb1806c2fb0b81e381a9881530bc | C11: 2026-04-29 17:31:47 | D11: 2026-04-29 | E11: receive | F11: TRUE | G11: FALSE | H11: ethereum | I11: USDT | J11: Tether USD | K11: 62390 | L11: 0.999363 | M11: 62350.25 | N11: 0x37268d9f8d4ff9c5c6137e97743e9cb56956aa5d | P11: 0xe1292b932090f022c2fc7830b24803635426bf3c305db75b4bc9ff123083d9e0
A12: Adamo OTC | B12: 0x2f58b30bd40fcb1806c2fb0b81e381a9881530bc | C12: 2026-04-26 20:07:23 | D12: 2026-04-26 | E12: receive | F12: TRUE | G12: FALSE | H12: ethereum | I12: USDT | J12: Tether USD | K12: 4875 | L12: 1.00068 | M12: 4878.32 | N12: 0xfb2a32475040f944983314e703686df926d5fec0 | P12: 0xf2ae29f01c23dbeb6f029f4ddcdede03786420ed141d86a865b8e8c2a340a3ce
A13: Adamo OTC | B13: 0x2f58b30bd40fcb1806c2fb0b81e381a9881530bc | C13: 2026-04-08 22:32:11 | D13: 2026-04-08 | E13: receive | F13: TRUE | G13: FALSE | H13: ethereum | I13: USDT | J13: Tether USD | K13: 19500 | L13: 1.000199 | M13: 19503.87 | N13: 0xfb2a32475040f944983314e703686df926d5fec0 | P13: 0x12b038296e7f13277c549f0833532f5dba9f2f72e306f1d81d9ddf6b524c15de
A14: Adamo OTC | B14: 0x2f58b30bd40fcb1806c2fb0b81e381a9881530bc | C14: 2026-03-20 09:01:35 | D14: 2026-03-20 | E14: receive | F14: TRUE | G14: FALSE | H14: ethereum | I14: USDT | J14: Tether USD | K14: 14625 | L14: 0.999973 | M14: 14624.6 | N14: 0x9fd8b9b58397c94aba4a61003e463ab0e79b2087 | P14: 0xcbb5b40729266ac3e2fe46773a4b8ecfe741eee1f498cd5073945932f967194d
A15: Adamo OTC | B15: 0x2f58b30bd40fcb1806c2fb0b81e381a9881530bc | C15: 2026-03-16 16:09:11 | D15: 2026-03-16 | E15: receive | F15: TRUE | G15: FALSE | H15: ethereum | I15: USDC | J15: USDC | K15: 7125 | L15: 1.001381 | M15: 7134.84 | N15: 0x0f82a63b101bc4a09791ed84561877820414f9ea | P15: 0x95ef6500cada7709fdc78af790592df38247494768066dbe0bedbcebc17384bb
A16: Adamo OTC | B16: 0x2f58b30bd40fcb1806c2fb0b81e381a9881530bc | C16: 2026-02-24 17:24:11 | D16: 2026-02-24 | E16: receive | F16: TRUE | G16: FALSE | H16: ethereum | I16: USDT | J16: Tether USD | K16: 77600 | L16: 1.000018 | M16: 77601.39 | N16: 0x5f4713a550f74eba2ab22670c60c27c6b96b8ebf | P16: 0xfafb91793f0a9953de427d0aebe21b8170f12c96cd48767a93f139f64dfc8b14
... A57: Adamo OTC | B57: 0x2f58b30bd40fcb1806c2fb0b81e381a9881530bc | C57: 2026-01-07 23:24:23 | D57: 2026-01-07 | E57: receive | F57: TRUE | G57: FALSE | H57: ethereum | I57: USDT | J57: Tether USD | K57: 26449.782 | L57: 1.000705 | M57: 26468.43 | N57: 0x9642b23ed1e01df1092b92641051881a322f5d4e | P57: 0x7b13c7daf0085859ca43941df2072ef81a6166cd2cb0d61b9831aad69d496ba1
A58: Adamo OTC | B58: 0x2f58b30bd40fcb1806c2fb0b81e381a9881530bc | C58: 2026-01-07 23:18:59 | D58: 2026-01-07 | E58: receive | F58: TRUE | G58: TRUE | H58: ethereum | I58: USDC | J58: USDC | K58: 6000 | L58: 1.002826 | M58: 6016.95 | N58: 0x9244a6962d8f2eefdcfec223f68d83df293d9797 | O58: Brute OTC | P58: 0xaa77f80cdfd62e231f25900136a3717df37feb5981df0fdb586f13ce7f30e7a4
A59: Adamo OTC | B59: 0x2f58b30bd40fcb1806c2fb0b81e381a9881530bc | C59: 2026-01-06 23:55:35 | D59: 2026-01-06 | E59: receive | F59: TRUE | G59: FALSE | H59: ethereum | I59: USDC | J59: USDC | K59: 24125 | L59: 0.999897 | M59: 24122.52 | N59: 0x0f82a63b101bc4a09791ed84561877820414f9ea | P59: 0x28178522073b7e39bbe25cc777272c3b4478f13ecfc45d41682b48ed2b32f56a
A60: Adamo OTC | B60: 0x2f58b30bd40fcb1806c2fb0b81e381a9881530bc | C60: 2026-01-06 22:28:47 | D60: 2026-01-06 | E60: trade | F60: FALSE | G60: FALSE | H60: ethereum | I60: USDT | J60: Tether USD | K60: 7052.1394 | L60: 1.000492 | M60: 7055.61 | N60: 0x45312ea0eff7e09c83cbe249fa1d7598c4c8cd4e | P60: 0x44a3e04e0c43e737ce465b3d281faf6fd7cf070e22b6f3835ecb85963d3fad59
A61: Adamo OTC | B61: 0x2f58b30bd40fcb1806c2fb0b81e381a9881530bc | C61: 2026-01-06 18:51:11 | D61: 2026-01-06 | E61: receive | F61: TRUE | G61: FALSE | H61: ethereum | I61: USDC | J61: USDC | K61: 10000 | L61: 1.000417 | M61: 10004.17 | N61: 0xf2016acdcfef869142d5e78a22ca9d5dae32468e | P61: 0xed9627803447ce4d5a8ef5bd0397a952af3806e5946fd8000499ba9ae5431cdd
A62: Adamo OTC | B62: 0x2f58b30bd40fcb1806c2fb0b81e381a9881530bc | C62: 2026-01-06 18:50:35 | D62: 2026-01-06 | E62: receive | F62: TRUE | G62: FALSE | H62: ethereum | I62: USDT | J62: Tether USD | K62: 30000 | L62: 0.998592 | M62: 29957.75 | N62: 0xf2016acdcfef869142d5e78a22ca9d5dae32468e | P62: 0x885a11d71684616b5f6e593def2f705dfb84478cf0a91655622fda683e453f12
A63: Adamo OTC | B63: 0x2f58b30bd40fcb1806c2fb0b81e381a9881530bc | C63: 2026-01-06 17:06:11 | D63: 2026-01-06 | E63: trade | F63: FALSE | G63: FALSE | H63: ethereum | I63: USDC | J63: USDC | K63: 2004.7353 | L63: 1.000366 | M63: 2005.47 | N63: 0x45312ea0eff7e09c83cbe249fa1d7598c4c8cd4e | P63: 0xec06870ae115e8ac48b448305c25e6e5ccd8d30c13b77db0ec7837f33f1abc73
A64: Adamo OTC | B64: 0x2f58b30bd40fcb1806c2fb0b81e381a9881530bc | C64: 2026-01-06 17:05:35 | D64: 2026-01-06 | E64: trade | F64: FALSE | G64: FALSE | H64: ethereum | I64: USDC | J64: USDC | K64: 14370.135 | L64: 1.000062 | M64: 14371.03 | N64: 0x45312ea0eff7e09c83cbe249fa1d7598c4c8cd4e | P64: 0x48ada189925db047e18f966aac57cfb23b5c25d8c6b6f746ecc03151ccd4e235
A65: Adamo OTC | B65: 0x2f58b30bd40fcb1806c2fb0b81e381a9881530bc | C65: 2026-01-05 23:58:11 | D65: 2026-01-05 | E65: receive | F65: TRUE | G65: FALSE | H65: ethereum | I65: USDT | J65: Tether USD | K65: 19400 | L65: 1.000082 | M65: 19401.59 | N65: 0x3685908e56acc83f3ee61b696ed59c32a6d6abb7 | P65: 0x9e5aa34fda92be3ba3e8b7ec158c45bc53e6d0cc0944d636d5d7330919436413
A66: Adamo OTC | B66: 0x2f58b30bd40fcb1806c2fb0b81e381a9881530bc | C66: 2026-01-05 23:04:11 | D66: 2026-01-05 | E66: receive | F66: TRUE | G66: FALSE | H66: ethereum | I66: USDT | J66: Tether USD | K66: 4862.5 | L66: 0.999926 | M66: 4862.14 | N66: 0xaa8ba7d4611437141192e7ceced531bc0a133efb | P66: 0xa26d79de95407da142b13cf9f2ced2c77d9ce911046c5769c46a48c90c8efd12
A67: Adamo OTC | B67: 0x2f58b30bd40fcb1806c2fb0b81e381a9881530bc | C67: 2026-01-05 12:46:35 | D67: 2026-01-05 | E67: receive | F67: TRUE | G67: FALSE | H67: ethereum | I67: USDC | J67: USDC | K67: 27160 | L67: 1.000003 | M67: 27160.09 | N67: 0x0f82a63b101bc4a09791ed84561877820414f9ea | P67: 0xf88904bfe31ea7f87fd70d021d64880ec99608f1546c5854ad9cdfea0eb934aa
A68: Adamo OTC | B68: 0x2f58b30bd40fcb1806c2fb0b81e381a9881530bc | C68: 2026-01-05 02:58:47 | D68: 2026-01-05 | E68: receive | F68: TRUE | G68: FALSE | H68: ethereum | I68: USDT | J68: Tether USD | K68: 23401.25 | L68: 0.999702 | M68: 23394.27 | N68: 0x5e67dbf6d2d1af434eed4c20cf7eca2591d4d4a6 | P68: 0xc1a246f96f44cecf737881639173e1ff1270a500bb2feb5826dcc54b753528fd
A69: Adamo OTC | B69: 0x2f58b30bd40fcb1806c2fb0b81e381a9881530bc | C69: 2026-01-04 21:09:59 | D69: 2026-01-04 | E69: receive | F69: TRUE | G69: FALSE | H69: ethereum | I69: USDT | J69: Tether USD | K69: 27985 | L69: 0.999767 | M69: 27978.49 | N69: 0x5e67dbf6d2d1af434eed4c20cf7eca2591d4d4a6 | P69: 0xc32af5042612f784ce65a86a37c6eedf01e4bb8b85696c486eb810ebc7ac2004
A70: Adamo OTC | B70: 0x2f58b30bd40fcb1806c2fb0b81e381a9881530bc | C70: 2026-01-03 20:23:11 | D70: 2026-01-03 | E70: receive | F70: TRUE | G70: FALSE | H70: ethereum | I70: USDT | J70: Tether USD | K70: 14999 | L70: 0.999835 | M70: 14996.52 | N70: 0x56eddb7aa87536c09ccc2793473599fd21a8b17f | P70: 0x941e6941d141b990b45c24b131d6e64793e3b68e104382a196b37fb47556bbb8
... A364: SP4-2 | B364: 0x31a5817bab67bfeeb0038df2c2e1ede79a00930a | C364: 2026-07-03 02:06:47 | D364: 2026-07-03 | E364: receive | F364: TRUE | G364: FALSE | H364: ethereum | I364: USDT | J364: Tether USD | K364: 4850 | L364: 0.997897 | M364: 4839.8 | N364: 0xaecd0b94f8d67b9af8fb9fd2addeb63f433406e6 | P364: 0x03cc40befaaf8c4605fe4d6e0a4720563089ff5a3710c62d59d1aac6414162bd
A365: SP4-3 | B365: 0x691bdfb0c5a8dee9f75de8bc983bde51316eb489 | C365: 2026-07-02 19:34:11 | D365: 2026-07-02 | E365: receive | F365: TRUE | G365: TRUE | H365: ethereum | I365: USDC | J365: USDC | K365: 1500 | L365: 1.000214 | M365: 1500.32 | N365: 0x9244a6962d8f2eefdcfec223f68d83df293d9797 | O365: Brute OTC | P365: 0x9a76f4825ad7698b84d730a6531845f824e36ddddacdda3d279f39194075c239
A366: SP4-4 | B366: 0x0828c3d976b837e790715913cc85dbd6237398fb | C366: 2026-07-08 20:39:35 | D366: 2026-07-08 | E366: receive | F366: TRUE | G366: FALSE | H366: ethereum | I366: USDT | J366: Tether USD | K366: 4000 | L366: 0.999304 | M366: 3997.22 | N366: 0xe161e68b13fa26df9570afb6d785df5270ecb8c4 | P366: 0x34ca1a70a8b53e06f5b70f03f16c8a2b2ee1d69938728319fe5dd9cbaf6f0f9d
A367: SP4-5 | B367: 0x79b65b17af2ec4087d0957bcfae172c3c6210312 | C367: 2026-07-08 01:27:35 | D367: 2026-07-08 | E367: receive | F367: TRUE | G367: FALSE | H367: ethereum | I367: USDC | J367: USDC | K367: 72905.832 | L367: 0.999739 | M367: 72886.77 | N367: 0x37ecb40eba8811f080247e18b81336ee2e2e791d | P367: 0xb0ce8fcd9dce07a89fc84027429f6e791d2a266711879ccf5612a661dbe51a3e
A368: SP4-6 | B368: 0x82012f9fdddaaf6a8af4ef2b83b1c6ce65debcf1 | C368: 2026-08-13 03:47:23 | D368: 2026-08-13 | E368: receive | F368: TRUE | G368: FALSE | H368: ethereum | I368: USDC | J368: USDC | K368: 14511 | L368: 0.999495 | M368: 14503.66 | N368: 0x11597afef0a96e6e948d739fe74ff84e6043d7a4 | P368: 0xf37332d3d9c684a75f559fc464f331a1787d8d81d4c79e134d7d382bdecec3d0
A369: SP4-6 | B369: 0x82012f9fdddaaf6a8af4ef2b83b1c6ce65debcf1 | C369: 2026-08-12 15:21:23 | D369: 2026-08-12 | E369: receive | F369: TRUE | G369: FALSE | H369: ethereum | I369: USDT | J369: Tether USD | K369: 16000 | L369: 0.999255 | M369: 15988.07 | N369: 0x9b06307970396965c9b66a7bece6df752b03333a | P369: 0x3cfbbd5d4ab2027d3838e7559d797bfeeec17b978e50160229445f0d69a3a310
A370: SP4-6 | B370: 0x82012f9fdddaaf6a8af4ef2b83b1c6ce65debcf1 | C370: 2026-07-24 19:15:59 | D370: 2026-07-24 | E370: receive | F370: TRUE | G370: FALSE | H370: ethereum | I370: USDT | J370: Tether USD | K370: 29273.419 | L370: 0.999141 | M370: 29248.28 | N370: 0x940bb47491ab320866d3f38288ba3d939f06f513 | P370: 0xa35bf5ce406b9f91498dee20a5acd353f3c34c57e90bb8c1c337b5bb64fdbf68
A371: SP4-6 | B371: 0x82012f9fdddaaf6a8af4ef2b83b1c6ce65debcf1 | C371: 2026-07-23 18:34:59 | D371: 2026-07-23 | E371: receive | F371: TRUE | G371: FALSE | H371: ethereum | I371: USDT | J371: Tether USD | K371: 54315.196 | L371: 0.999337 | M371: 54279.2 | N371: 0x940bb47491ab320866d3f38288ba3d939f06f513 | P371: 0x2c65e039132ac3a81c6d02e52cc84e664ba4712ce326006670096b79563c52a4
A372: SP4-6 | B372: 0x82012f9fdddaaf6a8af4ef2b83b1c6ce65debcf1 | C372: 2026-07-21 19:02:23 | D372: 2026-07-21 | E372: receive | F372: TRUE | G372: FALSE | H372: ethereum | I372: USDT | J372: Tether USD | K372: 29270.341 | L372: 0.999348 | M372: 29251.25 | N372: 0x940bb47491ab320866d3f38288ba3d939f06f513 | P372: 0xd35680e3546a4bf6fa12f274f419f6265e05c91d4d7420ce1e13eaf56f933eda
A373: SP4-7 | B373: 0xc4a749d6983bfc2bb958cb32ef9ff9dc18ba81cf | C373: 2026-07-23 16:42:47 | D373: 2026-07-23 | E373: receive | F373: TRUE | G373: FALSE | H373: ethereum | I373: USDC | J373: USDC | K373: 11640 | L373: 1.000061 | M373: 11640.71 | N373: 0xcecf534b3b0206d650f9b4a9b865a9889806301e | P373: 0xbed62d6689820fed27cb58e117026da6b7f9ff1ea34140faac201e395f459332
...
